<?xml version="1.0"?>
<robot name="sam_bot">

  <link name="base_link">
    <visual>
      <geometry>
        <box size="0.7 0.4 0.2"/>
      </geometry>
    </visual>
  </link>

  <link name="wheel_right_link">
    <visual>
      <geometry>
        <cylinder length="0.1" radius="0.2"/>
      </geometry>
      <origin rpy="1.57075 0 0" xyz="0 -0.05 0"/>
    </visual>
  </link>

  <joint name="wheel_right_joint" type="continuous">
    <parent link="base_link"/>
    <child link="wheel_right_link"/>
    <origin xyz="0.25 -0.2 -0.05"/>
    <axis xyz="0 1 0"/>
  </joint>

  <link name="wheel_left_link">
    <visual>
      <geometry>
        <cylinder length="0.1" radius="0.2"/>
      </geometry>
      <origin rpy="1.57075 0 0" xyz="0 0.05 0"/>
    </visual>
  </link>

  <joint name="wheel_left_joint" type="continuous">
    <parent link="base_link"/>
    <child link="wheel_left_link"/>
    <origin xyz="0.25 0.2 -0.05"/>
    <axis xyz="0 1 0"/>
  </joint>

</robot>
